Workbook

Sheet Справочник
A1: Линия | B1: Всего человек | E1: Линия | F1: Специальность | G1: Колво | H1: 1 смена | I1: Компетенция | J1: Статус | K1: 2 смена | L1: Компетенция 2 | M1: Статус 2 | N1: 3 смена | O1: Компетенция 3 | P1: Статус 3 | Q1: 4 смена | R1: Компетенция 4 | S1: Статус 4
A2: Линия 1–2 | B2: 8 | E2: Линия 3 | F2: Оператор - наладчик | G2: 1 | H2: Никитин Н. А. | I2: Оператор упаковщик, Оператор этикетки | K2: Костылев К. | N2: Кузнецов В. Ю. | Q2: Юров Р. А.
A3: Линия 3 | B3: 8 | E3: Линия 3 | F3: Оператор Депаллетайзера | G3: 1 | H3: Петелина О. С. | K3: Мурлыкина Н. В. | N3: Колянникова А. А. | Q3: Васин Д.
A4: Линия 4 | B4: 7 | E4: Линия 3 | F4: Оператор упаковщик | G4: 1 | H4: Костиков А. | K4: Докукин И. Н. | N4: Коробкин К. И. | Q4: Рахимзода А.
A5: Линия 5 | B5: 8 | E5: Линия 3 | F5: Оператор этикетки | G5: 1 | H5: Селуянова С. А. | K5: Ананьева Л. В. | N5: Митичкина Г. А. | Q5: Чумичёва О. С.
A6: Линия 6 | B6: 10 | E6: Линия 3 | F6: Подсобник | G6: 4 | H6: Иванов С.,Набиева Э. | K6: Нуриддинова Н. | Q6: Бурмистрова Е.
A7: Линия 7 | B7: 4 | E7: Линия 10 | F7: Оператор - наладчик | G7: 1 | K7: Бекташева Х. | N7: Борча С. А. | Q7: Шахов Н. С.
A8: Линия 8 | B8: 4 | E8: Линия 10 | F8: Оператор этикетки | G8: 1 | K8: Мурлыкина Р. С. | N8: Фандеева Т. В.
A9: Линия 9 | B9: 10 | E9: Линия 10 | F9: Подсобник | G9: 1
A10: Линия 10 | B10: 4 | E10: Линия 10 | F10: Подсобник лотки | G10: 1 | H10: Камакина Т. Л. | K10: Замосковная А. Н. | N10: Пенькова К.
A11: Линия 11 | B11: 8 | E11: Линия 11 | F11: Оператор - наладчик | G11: 1 | Q11: Булавинцева А.
A12: Соусы | B12: 3 | E12: Линия 11 | F12: Оператор Депаллетайзера | G12: 1
A13: Итого | B13: 69 | E13: Линия 11 | F13: Оператор Паллетайзера | G13: 1
E14: Линия 11 | F14: Оператор упаковщик | G14: 1
E15: Линия 11 | F15: Оператор этикетки | G15: 1
E16: Линия 11 | F16: Подсобник | G16: 3
E17: Линия 1-2 | F17: Оператор - наладчик | G17: 1 | H17: Ревякин А. М. | K17: Борняков С. В. | N17: Масалов С. И. | Q17: Гордеева О. А.
E18: Линия 1-2 | F18: Оператор Депаллетайзера | G18: 1 | H18: Набиева Р. | K18: Козлова М. Н. | N18: Маркина Е. Н. | Q18: Мирза Е. А.
E19: Линия 1-2 | F19: Оператор упаковщик | G19: 1
E20: Линия 1-2 | F20: Оператор этикетки | G20: 1 | H20: Саврук М. Ю. | K20: Меркулова А. В. | N20: Молокова С. И. | Q20: Миронова Е.
E21: Линия 1-2 | F21: Подсобник | G21: 4 | H21: Смирнова Н. В. | K21: Шаруева | N21: Ковальчук В. Г.,Возняк С. М. | Q21: Беликова Г.
E22: Линия 4 | F22: Оператор - наладчик | G22: 1 | H22: Чекулаев Д. М. | K22: Костылев А. | Q22: Фетисов Д. С.
E23: Линия 4 | F23: Оператор Депаллетайзера | G23: 1 | K23: Курбатова Е. А. | Q23: Лисицкая Т. Ф.
E24: Линия 4 | F24: Оператор упаковщик | G24: 1
E25: Линия 4 | F25: Оператор этикетки | G25: 1 | H25: Абрамова Е. Н. | K25: Горбунова Е. В. | N25: Косарева В. В. | Q25: Киреева А.
E26: Линия 4 | F26: Подсобник | G26: 3 | K26: Нуриддинова М. | Q26: Савоськин Р. А.
E27: Линия 5 | F27: Оператор - наладчик | G27: 1 | H27: Волкова С. Р. | K27: Кучерова | N27: Федоров М. С. | Q27: Карпухина Ю.
E28: Линия 5 | F28: Оператор Депаллетайзера | G28: 1 | H28: Лисицкая Е. В. | I28: Подсобник - обмотчик | K28: Саргсян М. | L28: Подсобник - обмотчик | N28: Филимонова О. Г. | O28: Подсобник - обмотчик | Q28: Никишова Н. | R28: Подсобник - обмотчик
E29: Линия 5 | F29: Оператор упаковщик | G29: 1 | H29: Сергеев А. А. | K29: Аванесян А. Б. | N29: Беликов И. Д. | Q29: Сидиков Н.
E30: Линия 5 | F30: Оператор этикетки | G30: 1 | H30: Сергеева М. Ю. | K30: Савушкина Е. | N30: Конова В. С. | Q30: Кулябина Н. А.
E31: Линия 5 | F31: Подсобник | G31: 4 | H31: Лянге Д. В. | K31: Абдулаева Ш.Х | N31: Порогин И. Ю.
E32: Линия 6 | F32: Оператор - наладчик | G32: 1 | H32: Налеткин С.С.
E33: Линия 6 | F33: Оператор упаковщик | G33: 1
E34: Линия 6 | F34: Подсобник | G34: 8
E35: Линия 7 | F35: Оператор - наладчик | G35: 1 | H35: Данелян А. Ф. | K35: Королькевич | Q35: Суховая В.
E36: Линия 7 | F36: Подсобник | G36: 3 | N36: Никифорова Н. Н.
E37: Линия 8 | F37: Оператор упаковщик | G37: 1
E38: Линия 8 | F38: Подсобник | G38: 3
E39: Линия 9 | F39: Оператор - наладчик | G39: 1
E40: Линия 9 | F40: Подсобник | G40: 9
...

Sheet Линия 1
A1: Линия розлива №1
A2: Дата начала | B2: Дата конца | C2: Длительность | D2: Скорость | E2: Наименование | F2: Количество | G2: Шт. в поддоне | H2: Кол-во поддоном
C3: =IF(E3="Вытеснение",TIME(0,30,0), IF(E3="Передача смены",TIME(0,20,0), IF(E3="Запуск",TIME(0,30,0), IF(E3="Смена ассортимента",TIME(0,15,0), IF(E3="Переналадка формата",TIME(1,0,0), IF(E3="CIP 1",TIME(0,40,0), IF(E3="CIP 2",TIME(4,0,0), IF(E3="CIP 3",TIME(5,0,0), IF(AND(ISNUMBER(F3),ISNUMBER(D3),D3>0),F3/D3/24,"Ошибка"))))))))) -> 0.45833333 | D3: 1000 | F3: 11000 | G3: 300 | H3: =Линия1[[#This Row],[Количество]]/Линия1[[#This Row],[Шт. в поддоне]] -> 36.666667
A4: ='Линия 2'!B70 -> 46052.735 | B4: =Линия1[[#This Row],[Дата начала]]+Линия1[[#This Row],[Длительность]] -> 46052.902 | C4: =IF(E4="Вытеснение",TIME(0,30,0), IF(E4="Передача смены",TIME(0,20,0), IF(E4="Запуск",TIME(0,30,0), IF(E4="Смена ассортимента",TIME(0,15,0), IF(E4="Переналадка формата",TIME(1,0,0), IF(E4="CIP 1",TIME(0,40,0), IF(E4="CIP 2",TIME(4,0,0), IF(E4="CIP 3",TIME(5,0,0), IF(AND(ISNUMBER(F4),ISNUMBER(D4),D4>0),F4/D4/24,"Ошибка"))))))))) -> 0.16666667 | E4: CIP 2 | H4: =IFERROR(Линия1[[#This Row],[Количество]]/Линия1[[#This Row],[Шт. в поддоне]], "")
A5: =B4 -> 46052.902 | B5: =Линия1[[#This Row],[Дата начала]]+Линия1[[#This Row],[Длительность]] -> 46053.36 | C5: =IF(E5="Вытеснение",TIME(0,30,0), IF(E5="Передача смены",TIME(0,20,0), IF(E5="Запуск",TIME(0,30,0), IF(E5="Смена ассортимента",TIME(0,15,0), IF(E5="Переналадка формата",TIME(1,0,0), IF(E5="CIP 1",TIME(0,40,0), IF(E5="CIP 2",TIME(4,0,0), IF(E5="CIP 3",TIME(5,0,0), IF(AND(ISNUMBER(F5),ISNUMBER(D5),D5>0),F5/D5/24,"Ошибка"))))))))) -> 0.45833333 | D5: 1000 | E5: Сок Яблоко 1,8 л ТМ «Полезный Сок» | F5: 11000 | G5: 300 | H5: =IFERROR(Линия1[[#This Row],[Количество]]/Линия1[[#This Row],[Шт. в поддоне]], "") -> 36.666667
A6: =B5 -> 46053.36 | B6: =Линия1[[#This Row],[Дата начала]]+Линия1[[#This Row],[Длительность]] -> 46053.527 | C6: =IF(E6="Вытеснение",TIME(0,30,0), IF(E6="Передача смены",TIME(0,20,0), IF(E6="Запуск",TIME(0,30,0), IF(E6="Смена ассортимента",TIME(0,15,0), IF(E6="Переналадка формата",TIME(1,0,0), IF(E6="CIP 1",TIME(0,40,0), IF(E6="CIP 2",TIME(4,0,0), IF(E6="CIP 3",TIME(5,0,0), IF(AND(ISNUMBER(F6),ISNUMBER(D6),D6>0),F6/D6/24,"Ошибка"))))))))) -> 0.16666667 | E6: CIP 2 | H6: =IFERROR(Линия1[[#This Row],[Количество]]/Линия1[[#This Row],[Шт. в поддоне]], "")
A7: =B6 -> 46053.527 | B7: =Линия1[[#This Row],[Дата начала]]+Линия1[[#This Row],[Длительность]] -> 46053.985 | C7: =IF(E7="Вытеснение",TIME(0,30,0), IF(E7="Передача смены",TIME(0,20,0), IF(E7="Запуск",TIME(0,30,0), IF(E7="Смена ассортимента",TIME(0,15,0), IF(E7="Переналадка формата",TIME(1,0,0), IF(E7="CIP 1",TIME(0,40,0), IF(E7="CIP 2",TIME(4,0,0), IF(E7="CIP 3",TIME(5,0,0), IF(AND(ISNUMBER(F7),ISNUMBER(D7),D7>0),F7/D7/24,"Ошибка"))))))))) -> 0.45833333 | D7: 1000 | E7: Сок Морковь 1,8 л ТМ «Полезный Сок» | F7: 11000 | G7: 300 | H7: =IFERROR(Линия1[[#This Row],[Количество]]/Линия1[[#This Row],[Шт. в поддоне]], "") -> 36.666667
A8: =B7 -> 46053.985 | B8: =Линия1[[#This Row],[Дата начала]]+Линия1[[#This Row],[Длительность]] -> 46054.152 | C8: =IF(E8="Вытеснение",TIME(0,30,0), IF(E8="Передача смены",TIME(0,20,0), IF(E8="Запуск",TIME(0,30,0), IF(E8="Смена ассортимента",TIME(0,15,0), IF(E8="Переналадка формата",TIME(1,0,0), IF(E8="CIP 1",TIME(0,40,0), IF(E8="CIP 2",TIME(4,0,0), IF(E8="CIP 3",TIME(5,0,0), IF(AND(ISNUMBER(F8),ISNUMBER(D8),D8>0),F8/D8/24,"Ошибка"))))))))) -> 0.16666667 | E8: CIP 2 | H8: =IFERROR(Линия1[[#This Row],[Количество]]/Линия1[[#This Row],[Шт. в поддоне]], "")
A9: =B8 -> 46054.152 | B9: =Линия1[[#This Row],[Дата начала]]+Линия1[[#This Row],[Длительность]] -> 46054.61 | C9: =IF(E9="Вытеснение",TIME(0,30,0), IF(E9="Передача смены",TIME(0,20,0), IF(E9="Запуск",TIME(0,30,0), IF(E9="Смена ассортимента",TIME(0,15,0), IF(E9="Переналадка формата",TIME(1,0,0), IF(E9="CIP 1",TIME(0,40,0), IF(E9="CIP 2",TIME(4,0,0), IF(E9="CIP 3",TIME(5,0,0), IF(AND(ISNUMBER(F9),ISNUMBER(D9),D9>0),F9/D9/24,"Ошибка"))))))))) -> 0.45833333 | D9: 1000 | E9: Сок Тыква 1,8 л ТМ «Полезный Сок» | F9: 11000 | G9: 300 | H9: =IFERROR(Линия1[[#This Row],[Количество]]/Линия1[[#This Row],[Шт. в поддоне]], "") -> 36.666667
A10: =B9 -> 46054.61 | B10: =Линия1[[#This Row],[Дата начала]]+Линия1[[#This Row],[Длительность]] -> 46054.777 | C10: =IF(E10="Вытеснение",TIME(0,30,0), IF(E10="Передача смены",TIME(0,20,0), IF(E10="Запуск",TIME(0,30,0), IF(E10="Смена ассортимента",TIME(0,15,0), IF(E10="Переналадка формата",TIME(1,0,0), IF(E10="CIP 1",TIME(0,40,0), IF(E10="CIP 2",TIME(4,0,0), IF(E10="CIP 3",TIME(5,0,0), IF(AND(ISNUMBER(F10),ISNUMBER(D10),D10>0),F10/D10/24,"Ошибка"))))))))) -> 0.16666667 | E10: CIP 2 | H10: =IFERROR(Линия1[[#This Row],[Количество]]/Линия1[[#This Row],[Шт. в поддоне]], "")
A11: =B10 -> 46054.777 | B11: =Линия1[[#This Row],[Дата начала]]+Линия1[[#This Row],[Длительность]] -> 46055.235 | C11: =IF(E11="Вытеснение",TIME(0,30,0), IF(E11="Передача смены",TIME(0,20,0), IF(E11="Запуск",TIME(0,30,0), IF(E11="Смена ассортимента",TIME(0,15,0), IF(E11="Переналадка формата",TIME(1,0,0), IF(E11="CIP 1",TIME(0,40,0), IF(E11="CIP 2",TIME(4,0,0), IF(E11="CIP 3",TIME(5,0,0), IF(AND(ISNUMBER(F11),ISNUMBER(D11),D11>0),F11/D11/24,"Ошибка"))))))))) -> 0.45833333 | D11: 1000 | E11: Сок Томат 1,8 л ТМ «Полезный Сок» | F11: 11000 | G11: 300 | H11: =IFERROR(Линия1[[#This Row],[Количество]]/Линия1[[#This Row],[Шт. в поддоне]], "") -> 36.666667
A12: =B11 -> 46055.235 | B12: =Линия1[[#This Row],[Дата начала]]+Линия1[[#This Row],[Длительность]] -> 46055.443 | C12: =IF(E12="Вытеснение",TIME(0,30,0), IF(E12="Передача смены",TIME(0,20,0), IF(E12="Запуск",TIME(0,30,0), IF(E12="Смена ассортимента",TIME(0,15,0), IF(E12="Переналадка формата",TIME(1,0,0), IF(E12="CIP 1",TIME(0,40,0), IF(E12="CIP 2",TIME(4,0,0), IF(E12="CIP 3",TIME(5,0,0), IF(AND(ISNUMBER(F12),ISNUMBER(D12),D12>0),F12/D12/24,"Ошибка"))))))))) -> 0.20833333 | E12: CIP 3 | H12: =IFERROR(Линия1[[#This Row],[Количество]]/Линия1[[#This Row],[Шт. в поддоне]], "")
E13: Переход на линию 2

Sheet Линия 2
A1: Линия розлива №2
A2: Дата начала | B2: Дата конца | C2: Длительность | D2: Скорость | E2: Наименование | F2: Количество | G2: Шт. в поддоне | H2: Кол-во поддоном
A3: =#REF! -> #REF! | B3: =Линия2[[#This Row],[Дата начала]]+Линия2[[#This Row],[Длительность]] -> #REF! | C3: =IF(E3="Вытеснение",TIME(0,30,0), IF(E3="Передача смены",TIME(0,20,0), IF(E3="Запуск",TIME(0,30,0), IF(E3="Смена ассортимента",TIME(0,15,0), IF(E3="Переналадка формата",TIME(5,0,0), IF(E3="CIP 1",TIME(0,40,0), IF(E3="CIP 2",TIME(2,30,0), IF(E3="CIP 3",TIME(3,20,0), IF(AND(ISNUMBER(F3),ISNUMBER(D3),D3>0),F3/D3/24,"Ошибка"))))))))) -> Ошибка
A4: ='Линия 4'!B28 -> 0 | B4: =Линия2[[#This Row],[Дата начала]]+Линия2[[#This Row],[Длительность]] -> 0.10416667 | C4: =IF(E4="Вытеснение",TIME(0,30,0), IF(E4="Передача смены",TIME(0,20,0), IF(E4="Запуск",TIME(0,30,0), IF(E4="Смена ассортимента",TIME(0,15,0), IF(E4="Переналадка формата",TIME(5,0,0), IF(E4="CIP 1",TIME(0,40,0), IF(E4="CIP 2",TIME(2,30,0), IF(E4="CIP 3",TIME(3,20,0), IF(AND(ISNUMBER(F4),ISNUMBER(D4),D4>0),F4/D4/24,"Ошибка"))))))))) -> 0.10416667 | E4: CIP 2 | H4: =IFERROR(Линия2[[#This Row],[Количество]]/Линия2[[#This Row],[Шт. в поддоне]], "")
A5: =B4 -> 0.10416667 | B5: =Линия2[[#This Row],[Дата начала]]+Линия2[[#This Row],[Длительность]] -> 0.61698718 | C5: =IF(E5="Вытеснение",TIME(0,30,0), IF(E5="Передача смены",TIME(0,20,0), IF(E5="Запуск",TIME(0,30,0), IF(E5="Смена ассортимента",TIME(0,15,0), IF(E5="Переналадка формата",TIME(5,0,0), IF(E5="CIP 1",TIME(0,40,0), IF(E5="CIP 2",TIME(2,30,0), IF(E5="CIP 3",TIME(3,20,0), IF(AND(ISNUMBER(F5),ISNUMBER(D5),D5>0),F5/D5/24,"Ошибка"))))))))) -> 0.51282051 | D5: 6500 | E5: Сок Яблоко 0,25 л ТМ «100% Джус» | F5: 80000 | G5: 1728 | H5: =IFERROR(Линия2[[#This Row],[Количество]]/Линия2[[#This Row],[Шт. в поддоне]], "") -> 46.296296
A6: =B5 -> 0.61698718 | B6: =Линия2[[#This Row],[Дата начала]]+Линия2[[#This Row],[Длительность]] -> 0.63782051 | C6: =IF(E6="Вытеснение",TIME(0,30,0), IF(E6="Передача смены",TIME(0,20,0), IF(E6="Запуск",TIME(0,30,0), IF(E6="Смена ассортимента",TIME(0,15,0), IF(E6="Переналадка формата",TIME(5,0,0), IF(E6="CIP 1",TIME(0,40,0), IF(E6="CIP 2",TIME(2,30,0), IF(E6="CIP 3",TIME(3,20,0), IF(AND(ISNUMBER(F6),ISNUMBER(D6),D6>0),F6/D6/24,"Ошибка"))))))))) -> 0.020833333 | E6: Вытеснение | H6: =IFERROR(Линия2[[#This Row],[Количество]]/Линия2[[#This Row],[Шт. в поддоне]], "")
A7: =B6 -> 0.63782051 | B7: =Линия2[[#This Row],[Дата начала]]+Линия2[[#This Row],[Длительность]] -> 0.65865385 | C7: =IF(E7="Вытеснение",TIME(0,30,0), IF(E7="Передача смены",TIME(0,20,0), IF(E7="Запуск",TIME(0,30,0), IF(E7="Смена ассортимента",TIME(0,15,0), IF(E7="Переналадка формата",TIME(5,0,0), IF(E7="CIP 1",TIME(0,40,0), IF(E7="CIP 2",TIME(2,30,0), IF(E7="CIP 3",TIME(3,20,0), IF(AND(ISNUMBER(F7),ISNUMBER(D7),D7>0),F7/D7/24,"Ошибка"))))))))) -> 0.020833333 | E7: Запуск | H7: =IFERROR(Линия2[[#This Row],[Количество]]/Линия2[[#This Row],[Шт. в поддоне]], "")
A8: 45998.146 | B8: =Линия2[[#This Row],[Дата начала]]+Линия2[[#This Row],[Длительность]] -> 46001.223 | C8: =IF(E8="Вытеснение",TIME(0,30,0), IF(E8="Передача смены",TIME(0,20,0), IF(E8="Запуск",TIME(0,30,0), IF(E8="Смена ассортимента",TIME(0,15,0), IF(E8="Переналадка формата",TIME(5,0,0), IF(E8="CIP 1",TIME(0,40,0), IF(E8="CIP 2",TIME(2,30,0), IF(E8="CIP 3",TIME(3,20,0), IF(AND(ISNUMBER(F8),ISNUMBER(D8),D8>0),F8/D8/24,"Ошибка"))))))))) -> 3.0769231 | D8: 6500 | E8: Сок Гранат 0,25 л ТМ «100% Джус» | F8: 480000 | G8: 1728 | H8: =IFERROR(Линия2[[#This Row],[Количество]]/Линия2[[#This Row],[Шт. в поддоне]], "") -> 277.77778
A9: =B8 -> 46001.223 | B9: =Линия2[[#This Row],[Дата начала]]+Линия2[[#This Row],[Длительность]] -> 46001.362 | C9: =IF(E9="Вытеснение",TIME(0,30,0), IF(E9="Передача смены",TIME(0,20,0), IF(E9="Запуск",TIME(0,30,0), IF(E9="Смена ассортимента",TIME(0,15,0), IF(E9="Переналадка формата",TIME(5,0,0), IF(E9="CIP 1",TIME(0,40,0), IF(E9="CIP 2",TIME(2,30,0), IF(E9="CIP 3",TIME(3,20,0), IF(AND(ISNUMBER(F9),ISNUMBER(D9),D9>0),F9/D9/24,"Ошибка"))))))))) -> 0.13888889 | E9: CIP 3 | H9: =IFERROR(Линия2[[#This Row],[Количество]]/Линия2[[#This Row],[Шт. в поддоне]], "")
A10: =B9 -> 46001.362 | B10: =Линия2[[#This Row],[Дата начала]]+Линия2[[#This Row],[Длительность]] -> 46001.382 | C10: =IF(E10="Вытеснение",TIME(0,30,0), IF(E10="Передача смены",TIME(0,20,0), IF(E10="Запуск",TIME(0,30,0), IF(E10="Смена ассортимента",TIME(0,15,0), IF(E10="Переналадка формата",TIME(5,0,0), IF(E10="CIP 1",TIME(0,40,0), IF(E10="CIP 2",TIME(2,30,0), IF(E10="CIP 3",TIME(3,20,0), IF(AND(ISNUMBER(F10),ISNUMBER(D10),D10>0),F10/D10/24,"Ошибка"))))))))) -> 0.020833333 | E10: Запуск | H10: =IFERROR(Линия2[[#This Row],[Количество]]/Линия2[[#This Row],[Шт. в поддоне]], "")
A11: 46001.583 | B11: =Линия2[[#This Row],[Дата начала]]+Линия2[[#This Row],[Длительность]] -> 46002.609 | C11: =IF(E11="Вытеснение",TIME(0,30,0), IF(E11="Передача смены",TIME(0,20,0), IF(E11="Запуск",TIME(0,30,0), IF(E11="Смена ассортимента",TIME(0,15,0), IF(E11="Переналадка формата",TIME(5,0,0), IF(E11="CIP 1",TIME(0,40,0), IF(E11="CIP 2",TIME(2,30,0), IF(E11="CIP 3",TIME(3,20,0), IF(AND(ISNUMBER(F11),ISNUMBER(D11),D11>0),F11/D11/24,"Ошибка"))))))))) -> 1.025641 | D11: 6500 | E11: Нектар Манго 0,25 л ТМ «100% Джус» | F11: 160000 | G11: 1728 | H11: =IFERROR(Линия2[[#This Row],[Количество]]/Линия2[[#This Row],[Шт. в поддоне]], "") -> 92.592593
A12: =B11 -> 46002.609 | B12: =Линия2[[#This Row],[Дата начала]]+Линия2[[#This Row],[Длительность]] -> 46002.713 | C12: =IF(E12="Вытеснение",TIME(0,30,0), IF(E12="Передача смены",TIME(0,20,0), IF(E12="Запуск",TIME(0,30,0), IF(E12="Смена ассортимента",TIME(0,15,0), IF(E12="Переналадка формата",TIME(5,0,0), IF(E12="CIP 1",TIME(0,40,0), IF(E12="CIP 2",TIME(2,30,0), IF(E12="CIP 3",TIME(3,20,0), IF(AND(ISNUMBER(F12),ISNUMBER(D12),D12>0),F12/D12/24,"Ошибка"))))))))) -> 0.10416667 | E12: CIP 2 | H12: =IFERROR(Линия2[[#This Row],[Количество]]/Линия2[[#This Row],[Шт. в поддоне]], "")
A13: =B12 -> 46002.713 | B13: =Линия2[[#This Row],[Дата начала]]+Линия2[[#This Row],[Длительность]] -> 46002.734 | C13: =IF(E13="Вытеснение",TIME(0,30,0), IF(E13="Передача смены",TIME(0,20,0), IF(E13="Запуск",TIME(0,30,0), IF(E13="Смена ассортимента",TIME(0,15,0), IF(E13="Переналадка формата",TIME(5,0,0), IF(E13="CIP 1",TIME(0,40,0), IF(E13="CIP 2",TIME(2,30,0), IF(E13="CIP 3",TIME(3,20,0), IF(AND(ISNUMBER(F13),ISNUMBER(D13),D13>0),F13/D13/24,"Ошибка"))))))))) -> 0.020833333 | E13: Запуск | H13: =IFERROR(Линия2[[#This Row],[Количество]]/Линия2[[#This Row],[Шт. в поддоне]], "")
A14: 46002.958 | B14: =Линия2[[#This Row],[Дата начала]]+Линия2[[#This Row],[Длительность]] -> 46004.24 | C14: =IF(E14="Вытеснение",TIME(0,30,0), IF(E14="Передача смены",TIME(0,20,0), IF(E14="Запуск",TIME(0,30,0), IF(E14="Смена ассортимента",TIME(0,15,0), IF(E14="Переналадка формата",TIME(5,0,0), IF(E14="CIP 1",TIME(0,40,0), IF(E14="CIP 2",TIME(2,30,0), IF(E14="CIP 3",TIME(3,20,0), IF(AND(ISNUMBER(F14),ISNUMBER(D14),D14>0),F14/D14/24,"Ошибка"))))))))) -> 1.2820513 | D14: 6500 | E14: Нектар Банан-Киви 0,25 л ТМ «100% Джус» | F14: 200000 | G14: 1728 | H14: =IFERROR(Линия2[[#This Row],[Количество]]/Линия2[[#This Row],[Шт. в поддоне]], "") -> 115.74074
A15: =B14 -> 46004.24 | B15: =Линия2[[#This Row],[Дата начала]]+Линия2[[#This Row],[Длительность]] -> 46004.345 | C15: =IF(E15="Вытеснение",TIME(0,30,0), IF(E15="Передача смены",TIME(0,20,0), IF(E15="Запуск",TIME(0,30,0), IF(E15="Смена ассортимента",TIME(0,15,0), IF(E15="Переналадка формата",TIME(5,0,0), IF(E15="CIP 1",TIME(0,40,0), IF(E15="CIP 2",TIME(2,30,0), IF(E15="CIP 3",TIME(3,20,0), IF(AND(ISNUMBER(F15),ISNUMBER(D15),D15>0),F15/D15/24,"Ошибка"))))))))) -> 0.10416667 | E15: CIP 2 | H15: =IFERROR(Линия2[[#This Row],[Количество]]/Линия2[[#This Row],[Шт. в поддоне]], "")
A16: =B15 -> 46004.345 | B16: =Линия2[[#This Row],[Дата начала]]+Линия2[[#This Row],[Длительность]] -> 46004.365 | C16: =IF(E16="Вытеснение",TIME(0,30,0), IF(E16="Передача смены",TIME(0,20,0), IF(E16="Запуск",TIME(0,30,0), IF(E16="Смена ассортимента",TIME(0,15,0), IF(E16="Переналадка формата",TIME(5,0,0), IF(E16="CIP 1",TIME(0,40,0), IF(E16="CIP 2",TIME(2,30,0), IF(E16="CIP 3",TIME(3,20,0), IF(AND(ISNUMBER(F16),ISNUMBER(D16),D16>0),F16/D16/24,"Ошибка"))))))))) -> 0.020833333 | E16: Запуск | H16: =IFERROR(Линия2[[#This Row],[Количество]]/Линия2[[#This Row],[Шт. в поддоне]], "")
A17: =B16 -> 46004.365 | B17: =Линия2[[#This Row],[Дата начала]]+Линия2[[#This Row],[Длительность]] -> 46005.647 | C17: =IF(E17="Вытеснение",TIME(0,30,0), IF(E17="Передача смены",TIME(0,20,0), IF(E17="Запуск",TIME(0,30,0), IF(E17="Смена ассортимента",TIME(0,15,0), IF(E17="Переналадка формата",TIME(5,0,0), IF(E17="CIP 1",TIME(0,40,0), IF(E17="CIP 2",TIME(2,30,0), IF(E17="CIP 3",TIME(3,20,0), IF(AND(ISNUMBER(F17),ISNUMBER(D17),D17>0),F17/D17/24,"Ошибка"))))))))) -> 1.2820513 | D17: 6500 | E17: Сок Груша 0,25 л ТМ «100% Джус» | F17: 200000 | G17: 1728 | H17: =IFERROR(Линия2[[#This Row],[Количество]]/Линия2[[#This Row],[Шт. в поддоне]], "") -> 115.74074
A18: =B17 -> 46005.647 | B18: =Линия2[[#This Row],[Дата начала]]+Линия2[[#This Row],[Длительность]] -> 46005.786 | C18: =IF(E18="Вытеснение",TIME(0,30,0), IF(E18="Передача смены",TIME(0,20,0), IF(E18="Запуск",TIME(0,30,0), IF(E18="Смена ассортимента",TIME(0,15,0), IF(E18="Переналадка формата",TIME(5,0,0), IF(E18="CIP 1",TIME(0,40,0), IF(E18="CIP 2",TIME(2,30,0), IF(E18="CIP 3",TIME(3,20,0), IF(AND(ISNUMBER(F18),ISNUMBER(D18),D18>0),F18/D18/24,"Ошибка"))))))))) -> 0.13888889 | E18: CIP 3 | H18: =IFERROR(Линия2[[#This Row],[Количество]]/Линия2[[#This Row],[Шт. в поддоне]], "")
A19: =B18 -> 46005.786 | B19: =Линия2[[#This Row],[Дата начала]]+Линия2[[#This Row],[Длительность]] -> 46005.807 | C19: =IF(E19="Вытеснение",TIME(0,30,0), IF(E19="Передача смены",TIME(0,20,0), IF(E19="Запуск",TIME(0,30,0), IF(E19="Смена ассортимента",TIME(0,15,0), IF(E19="Переналадка формата",TIME(5,0,0), IF(E19="CIP 1",TIME(0,40,0), IF(E19="CIP 2",TIME(2,30,0), IF(E19="CIP 3",TIME(3,20,0), IF(AND(ISNUMBER(F19),ISNUMBER(D19),D19>0),F19/D19/24,"Ошибка"))))))))) -> 0.020833333 | E19: Запуск | H19: =IFERROR(Линия2[[#This Row],[Количество]]/Линия2[[#This Row],[Шт. в поддоне]], "")
A20: 46006.094 | B20: =Линия2[[#This Row],[Дата начала]]+Линия2[[#This Row],[Длительность]] -> 46009.3 | C20: =IF(E20="Вытеснение",TIME(0,30,0), IF(E20="Передача смены",TIME(0,20,0), IF(E20="Запуск",TIME(0,30,0), IF(E20="Смена ассортимента",TIME(0,15,0), IF(E20="Переналадка формата",TIME(5,0,0), IF(E20="CIP 1",TIME(0,40,0), IF(E20="CIP 2",TIME(2,30,0), IF(E20="CIP 3",TIME(3,20,0), IF(AND(ISNUMBER(F20),ISNUMBER(D20),D20>0),F20/D20/24,"Ошибка"))))))))) -> 3.2051282 | D20: 6500 | E20: Нектар Гранат 0,25 л ТМ «Дети» | F20: 500000 | G20: 1728 | H20: =IFERROR(Линия2[[#This Row],[Количество]]/Линия2[[#This Row],[Шт. в поддоне]], "") -> 289.35185
A21: =B20 -> 46009.3 | B21: =Линия2[[#This Row],[Дата начала]]+Линия2[[#This Row],[Длительность]] -> 46009.438 | C21: =IF(E21="Вытеснение",TIME(0,30,0), IF(E21="Передача смены",TIME(0,20,0), IF(E21="Запуск",TIME(0,30,0), IF(E21="Смена ассортимента",TIME(0,15,0), IF(E21="Переналадка формата",TIME(5,0,0), IF(E21="CIP 1",TIME(0,40,0), IF(E21="CIP 2",TIME(2,30,0), IF(E21="CIP 3",TIME(3,20,0), IF(AND(ISNUMBER(F21),ISNUMBER(D21),D21>0),F21/D21/24,"Ошибка"))))))))) -> 0.13888889 | E21: CIP 3 | H21: =IFERROR(Линия2[[#This Row],[Количество]]/Линия2[[#This Row],[Шт. в поддоне]], "")
A22: =B21 -> 46009.438 | B22: =Линия2[[#This Row],[Дата начала]]+Линия2[[#This Row],[Длительность]] -> 46009.459 | C22: =IF(E22="Вытеснение",TIME(0,30,0), IF(E22="Передача смены",TIME(0,20,0), IF(E22="Запуск",TIME(0,30,0), IF(E22="Смена ассортимента",TIME(0,15,0), IF(E22="Переналадка формата",TIME(5,0,0), IF(E22="CIP 1",TIME(0,40,0), IF(E22="CIP 2",TIME(2,30,0), IF(E22="CIP 3",TIME(3,20,0), IF(AND(ISNUMBER(F22),ISNUMBER(D22),D22>0),F22/D22/24,"Ошибка"))))))))) -> 0.020833333 | E22: Запуск | H22: =IFERROR(Линия2[[#This Row],[Количество]]/Линия2[[#This Row],[Шт. в поддоне]], "")
A23: =B22 -> 46009.459 | B23: =Линия2[[#This Row],[Дата начала]]+Линия2[[#This Row],[Длительность]] -> 46012.664 | C23: =IF(E23="Вытеснение",TIME(0,30,0), IF(E23="Передача смены",TIME(0,20,0), IF(E23="Запуск",TIME(0,30,0), IF(E23="Смена ассортимента",TIME(0,15,0), IF(E23="Переналадка формата",TIME(5,0,0), IF(E23="CIP 1",TIME(0,40,0), IF(E23="CIP 2",TIME(2,30,0), IF(E23="CIP 3",TIME(3,20,0), IF(AND(ISNUMBER(F23),ISNUMBER(D23),D23>0),F23/D23/24,"Ошибка"))))))))) -> 3.2051282 | D23: 6500 | E23: Нектар Гранат 0,25 л ТМ «Дети» | F23: 500000 | G23: 1728 | H23: =IFERROR(Линия2[[#This Row],[Количество]]/Линия2[[#This Row],[Шт. в поддоне]], "") -> 289.35185
A24: =B23 -> 46012.664 | B24: =Линия2[[#This Row],[Дата начала]]+Линия2[[#This Row],[Длительность]] -> 46012.803 | C24: =IF(E24="Вытеснение",TIME(0,30,0), IF(E24="Передача смены",TIME(0,20,0), IF(E24="Запуск",TIME(0,30,0), IF(E24="Смена ассортимента",TIME(0,15,0), IF(E24="Переналадка формата",TIME(5,0,0), IF(E24="CIP 1",TIME(0,40,0), IF(E24="CIP 2",TIME(2,30,0), IF(E24="CIP 3",TIME(3,20,0), IF(AND(ISNUMBER(F24),ISNUMBER(D24),D24>0),F24/D24/24,"Ошибка"))))))))) -> 0.13888889 | E24: CIP 3 | H24: =IFERROR(Линия2[[#This Row],[Количество]]/Линия2[[#This Row],[Шт. в поддоне]], "")
A25: =B24 -> 46012.803 | B25: =Линия2[[#This Row],[Дата начала]]+Линия2[[#This Row],[Длительность]] -> 46012.824 | C25: =IF(E25="Вытеснение",TIME(0,30,0), IF(E25="Передача смены",TIME(0,20,0), IF(E25="Запуск",TIME(0,30,0), IF(E25="Смена ассортимента",TIME(0,15,0), IF(E25="Переналадка формата",TIME(5,0,0), IF(E25="CIP 1",TIME(0,40,0), IF(E25="CIP 2",TIME(2,30,0), IF(E25="CIP 3",TIME(3,20,0), IF(AND(ISNUMBER(F25),ISNUMBER(D25),D25>0),F25/D25/24,"Ошибка"))))))))) -> 0.020833333 | E25: Запуск | H25: =IFERROR(Линия2[[#This Row],[Количество]]/Линия2[[#This Row],[Шт. в поддоне]], "")
A26: 46016.167 | B26: =Линия2[[#This Row],[Дата начала]]+Линия2[[#This Row],[Длительность]] -> 46018.731 | C26: =IF(E26="Вытеснение",TIME(0,30,0), IF(E26="Передача смены",TIME(0,20,0), IF(E26="Запуск",TIME(0,30,0), IF(E26="Смена ассортимента",TIME(0,15,0), IF(E26="Переналадка формата",TIME(5,0,0), IF(E26="CIP 1",TIME(0,40,0), IF(E26="CIP 2",TIME(2,30,0), IF(E26="CIP 3",TIME(3,20,0), IF(AND(ISNUMBER(F26),ISNUMBER(D26),D26>0),F26/D26/24,"Ошибка"))))))))) -> 2.5641026 | D26: 6500 | E26: Нектар Гранат 0,25 л ТМ «Дети» | F26: 400000 | G26: 1728 | H26: =IFERROR(Линия2[[#This Row],[Количество]]/Линия2[[#This Row],[Шт. в поддоне]], "") -> 231.48148
A27: =B26 -> 46018.731 | B27: =Линия2[[#This Row],[Дата начала]]+Линия2[[#This Row],[Длительность]] -> 46018.87 | C27: =IF(E27="Вытеснение",TIME(0,30,0), IF(E27="Передача смены",TIME(0,20,0), IF(E27="Запуск",TIME(0,30,0), IF(E27="Смена ассортимента",TIME(0,15,0), IF(E27="Переналадка формата",TIME(5,0,0), IF(E27="CIP 1",TIME(0,40,0), IF(E27="CIP 2",TIME(2,30,0), IF(E27="CIP 3",TIME(3,20,0), IF(AND(ISNUMBER(F27),ISNUMBER(D27),D27>0),F27/D27/24,"Ошибка"))))))))) -> 0.13888889 | E27: CIP 3 | H27: =IFERROR(Линия2[[#This Row],[Количество]]/Линия2[[#This Row],[Шт. в поддоне]], "")
A28: =B27 -> 46018.87 | B28: =Линия2[[#This Row],[Дата начала]]+Линия2[[#This Row],[Длительность]] -> 46020.216 | C28: =IF(E28="Вытеснение",TIME(0,30,0), IF(E28="Передача смены",TIME(0,20,0), IF(E28="Запуск",TIME(0,30,0), IF(E28="Смена ассортимента",TIME(0,15,0), IF(E28="Переналадка формата",TIME(5,0,0), IF(E28="CIP 1",TIME(0,40,0), IF(E28="CIP 2",TIME(2,30,0), IF(E28="CIP 3",TIME(3,20,0), IF(AND(ISNUMBER(F28),ISNUMBER(D28),D28>0),F28/D28/24,"Ошибка"))))))))) -> 1.3461538 | D28: 6500 | E28: Нектар Гранат 0,25 л ТМ «Дети» | F28: 210000 | G28: 1728 | H28: =IFERROR(Линия2[[#This Row],[Количество]]/Линия2[[#This Row],[Шт. в поддоне]], "") -> 121.52778
A29: =B28 -> 46020.216 | B29: =Линия2[[#This Row],[Дата начала]]+Линия2[[#This Row],[Длительность]] -> 46020.237 | C29: =IF(E29="Вытеснение",TIME(0,30,0), IF(E29="Передача смены",TIME(0,20,0), IF(E29="Запуск",TIME(0,30,0), IF(E29="Смена ассортимента",TIME(0,15,0), IF(E29="Переналадка формата",TIME(5,0,0), IF(E29="CIP 1",TIME(0,40,0), IF(E29="CIP 2",TIME(2,30,0), IF(E29="CIP 3",TIME(3,20,0), IF(AND(ISNUMBER(F29),ISNUMBER(D29),D29>0),F29/D29/24,"Ошибка"))))))))) -> 0.020833333 | E29: Вытеснение | H29: =IFERROR(Линия2[[#This Row],[Количество]]/Линия2[[#This Row],[Шт. в поддоне]], "")
A30: 46020.75 | B30: =Линия2[[#This Row],[Дата начала]]+Линия2[[#This Row],[Длительность]] -> 46021.519 | C30: =IF(E30="Вытеснение",TIME(0,30,0), IF(E30="Передача смены",TIME(0,20,0), IF(E30="Запуск",TIME(0,30,0), IF(E30="Смена ассортимента",TIME(0,15,0), IF(E30="Переналадка формата",TIME(5,0,0), IF(E30="CIP 1",TIME(0,40,0), IF(E30="CIP 2",TIME(2,30,0), IF(E30="CIP 3",TIME(3,20,0), IF(AND(ISNUMBER(F30),ISNUMBER(D30),D30>0),F30/D30/24,"Ошибка"))))))))) -> 0.76923077 | D30: 6500 | E30: Сок Гранат 0,25 л ТМ «100% Джус» | F30: 120000 | G30: 1728 | H30: =IFERROR(Линия2[[#This Row],[Количество]]/Линия2[[#This Row],[Шт. в поддоне]], "") -> 69.444444
A31: =B30 -> 46021.519 | B31: =Линия2[[#This Row],[Дата начала]]+Линия2[[#This Row],[Длительность]] -> 46021.658 | C31: =IF(E31="Вытеснение",TIME(0,30,0), IF(E31="Передача смены",TIME(0,20,0), IF(E31="Запуск",TIME(0,30,0), IF(E31="Смена ассортимента",TIME(0,15,0), IF(E31="Переналадка формата",TIME(5,0,0), IF(E31="CIP 1",TIME(0,40,0), IF(E31="CIP 2",TIME(2,30,0), IF(E31="CIP 3",TIME(3,20,0), IF(AND(ISNUMBER(F31),ISNUMBER(D31),D31>0),F31/D31/24,"Ошибка"))))))))) -> 0.13888889 | E31: CIP 3 | H31: =IFERROR(Линия2[[#This Row],[Количество]]/Линия2[[#This Row],[Шт. в поддоне]], "")
E32: 2026 год | H32: =IFERROR(Линия5[[#This Row],[Количество]]/Линия5[[#This Row],[Шт. в поддоне]], "")
A33: 46034.875 | B33: =Линия2[[#This Row],[Дата начала]]+Линия2[[#This Row],[Длительность]] -> 46035.644 | C33: =IF(E33="Вытеснение",TIME(0,30,0), IF(E33="Передача смены",TIME(0,20,0), IF(E33="Запуск",TIME(0,30,0), IF(E33="Смена ассортимента",TIME(0,15,0), IF(E33="Переналадка формата",TIME(5,0,0), IF(E33="CIP 1",TIME(0,40,0), IF(E33="CIP 2",TIME(2,30,0), IF(E33="CIP 3",TIME(3,20,0), IF(AND(ISNUMBER(F33),ISNUMBER(D33),D33>0),F33/D33/24,"Ошибка"))))))))) -> 0.76923077 | D33: 6500 | E33: Нектар Банан-Киви 0,25 л ТМ «100% Джус» | F33: 120000 | G33: 1728 | H33: =IFERROR(Линия2[[#This Row],[Количество]]/Линия2[[#This Row],[Шт. в поддоне]], "") -> 69.444444
A34: =B33 -> 46035.644 | B34: =Линия2[[#This Row],[Дата начала]]+Линия2[[#This Row],[Длительность]] -> 46035.748 | C34: =IF(E34="Вытеснение",TIME(0,30,0), IF(E34="Передача смены",TIME(0,20,0), IF(E34="Запуск",TIME(0,30,0), IF(E34="Смена ассортимента",TIME(0,15,0), IF(E34="Переналадка формата",TIME(5,0,0), IF(E34="CIP 1",TIME(0,40,0), IF(E34="CIP 2",TIME(2,30,0), IF(E34="CIP 3",TIME(3,20,0), IF(AND(ISNUMBER(F34),ISNUMBER(D34),D34>0),F34/D34/24,"Ошибка"))))))))) -> 0.10416667 | E34: CIP 2 | H34: =IFERROR(Линия2[[#This Row],[Количество]]/Линия2[[#This Row],[Шт. в поддоне]], "")
A35: =B34 -> 46035.748 | B35: =Линия2[[#This Row],[Дата начала]]+Линия2[[#This Row],[Длительность]] -> 46036.005 | C35: =IF(E35="Вытеснение",TIME(0,30,0), IF(E35="Передача смены",TIME(0,20,0), IF(E35="Запуск",TIME(0,30,0), IF(E35="Смена ассортимента",TIME(0,15,0), IF(E35="Переналадка формата",TIME(5,0,0), IF(E35="CIP 1",TIME(0,40,0), IF(E35="CIP 2",TIME(2,30,0), IF(E35="CIP 3",TIME(3,20,0), IF(AND(ISNUMBER(F35),ISNUMBER(D35),D35>0),F35/D35/24,"Ошибка"))))))))) -> 0.25641026 | D35: 6500 | E35: Сок Апельсин 0,25 л ТМ «100% Джус» | F35: 40000 | G35: 1728 | H35: =IFERROR(Линия2[[#This Row],[Количество]]/Линия2[[#This Row],[Шт. в поддоне]], "") -> 23.148148
A36: =B35 -> 46036.005 | B36: =Линия2[[#This Row],[Дата начала]]+Линия2[[#This Row],[Длительность]] -> 46036.026 | C36: =IF(E36="Вытеснение",TIME(0,30,0), IF(E36="Передача смены",TIME(0,20,0), IF(E36="Запуск",TIME(0,30,0), IF(E36="Смена ассортимента",TIME(0,15,0), IF(E36="Переналадка формата",TIME(5,0,0), IF(E36="CIP 1",TIME(0,40,0), IF(E36="CIP 2",TIME(2,30,0), IF(E36="CIP 3",TIME(3,20,0), IF(AND(ISNUMBER(F36),ISNUMBER(D36),D36>0),F36/D36/24,"Ошибка"))))))))) -> 0.020833333 | E36: Вытеснение | H36: =IFERROR(Линия2[[#This Row],[Количество]]/Линия2[[#This Row],[Шт. в поддоне]], "")
A37: 46036.208 | B37: =Линия2[[#This Row],[Дата начала]]+Линия2[[#This Row],[Длительность]] -> 46036.465 | C37: =IF(E37="Вытеснение",TIME(0,30,0), IF(E37="Передача смены",TIME(0,20,0), IF(E37="Запуск",TIME(0,30,0), IF(E37="Смена ассортимента",TIME(0,15,0), IF(E37="Переналадка формата",TIME(5,0,0), IF(E37="CIP 1",TIME(0,40,0), IF(E37="CIP 2",TIME(2,30,0), IF(E37="CIP 3",TIME(3,20,0), IF(AND(ISNUMBER(F37),ISNUMBER(D37),D37>0),F37/D37/24,"Ошибка"))))))))) -> 0.25641026 | D37: 6500 | E37: Нектар Персик 0,25 л ТМ «100% Джус» | F37: 40000 | G37: 1728 | H37: =IFERROR(Линия2[[#This Row],[Количество]]/Линия2[[#This Row],[Шт. в поддоне]], "") -> 23.148148
A38: =B37 -> 46036.465 | B38: =Линия2[[#This Row],[Дата начала]]+Линия2[[#This Row],[Длительность]] -> 46036.486 | C38: =IF(E38="Вытеснение",TIME(0,30,0), IF(E38="Передача смены",TIME(0,20,0), IF(E38="Запуск",TIME(0,30,0), IF(E38="Смена ассортимента",TIME(0,15,0), IF(E38="Переналадка формата",TIME(5,0,0), IF(E38="CIP 1",TIME(0,40,0), IF(E38="CIP 2",TIME(2,30,0), IF(E38="CIP 3",TIME(3,20,0), IF(AND(ISNUMBER(F38),ISNUMBER(D38),D38>0),F38/D38/24,"Ошибка"))))))))) -> 0.020833333 | E38: Вытеснение | H38: =IFERROR(Линия2[[#This Row],[Количество]]/Линия2[[#This Row],[Шт. в поддоне]], "")
A39: =B38 -> 46036.486 | B39: =Линия2[[#This Row],[Дата начала]]+Линия2[[#This Row],[Длительность]] -> 46036.998 | C39: =IF(E39="Вытеснение",TIME(0,30,0), IF(E39="Передача смены",TIME(0,20,0), IF(E39="Запуск",TIME(0,30,0), IF(E39="Смена ассортимента",TIME(0,15,0), IF(E39="Переналадка формата",TIME(5,0,0), IF(E39="CIP 1",TIME(0,40,0), IF(E39="CIP 2",TIME(2,30,0), IF(E39="CIP 3",TIME(3,20,0), IF(AND(ISNUMBER(F39),ISNUMBER(D39),D39>0),F39/D39/24,"Ошибка"))))))))) -> 0.51282051 | D39: 6500 | E39: Нектар Манго 0,25 л ТМ «100% Джус» | F39: 80000 | G39: 1728 | H39: =IFERROR(Линия2[[#This Row],[Количество]]/Линия2[[#This Row],[Шт. в поддоне]], "") -> 46.296296
A40: =B39 -> 46036.998 | B40: =Линия2[[#This Row],[Дата начала]]+Линия2[[#This Row],[Длительность]] -> 46037.019 | C40: =IF(E40="Вытеснение",TIME(0,30,0), IF(E40="Передача смены",TIME(0,20,0), IF(E40="Запуск",TIME(0,30,0), IF(E40="Смена ассортимента",TIME(0,15,0), IF(E40="Переналадка формата",TIME(5,0,0), IF(E40="CIP 1",TIME(0,40,0), IF(E40="CIP 2",TIME(2,30,0), IF(E40="CIP 3",TIME(3,20,0), IF(AND(ISNUMBER(F40),ISNUMBER(D40),D40>0),F40/D40/24,"Ошибка"))))))))) -> 0.020833333 | E40: Вытеснение
...

Sheet Линия 3
A1: Линия розлива №3
A2: Дата начала | B2: Дата конца | C2: Длительность | D2: Скорость | E2: Наименование | F2: Количество | G2: Шт. в поддоне | H2: Кол-во поддоном
A3: =Линия3[[#This Row],[Дата конца]]-Линия3[[#This Row],[Длительность]] -> 45995.798 | B3: 45996.542 | C3: =IF(E3="Вытеснение",TIME(0,30,0), IF(E3="Передача смены",TIME(0,20,0), IF(E3="Запуск",TIME(0,30,0), IF(E3="Смена ассортимента",TIME(0,15,0), IF(E3="Переналадка формата",TIME(5,0,0), IF(E3="CIP 1",TIME(0,40,0), IF(E3="CIP 2",TIME(2,30,0), IF(E3="CIP 3",TIME(3,20,0), IF(AND(ISNUMBER(F3),ISNUMBER(D3),D3>0),F3/D3/24,"Ошибка"))))))))) -> 0.74324324 | D3: 3700 | E3: Нектар Тыква 0,75 л ТМ «Soko GRANDE» | F3: 66000 | G3: 756 | H3: =IFERROR(Линия3[[#This Row],[Количество]]/Линия3[[#This Row],[Шт. в поддоне]], "") -> 87.301587
A4: =B3 -> 45996.542 | B4: =Линия3[[#This Row],[Дата начала]]+Линия3[[#This Row],[Длительность]] -> 45996.646 | C4: =IF(E4="Вытеснение",TIME(0,30,0), IF(E4="Передача смены",TIME(0,20,0), IF(E4="Запуск",TIME(0,30,0), IF(E4="Смена ассортимента",TIME(0,15,0), IF(E4="Переналадка формата",TIME(5,0,0), IF(E4="CIP 1",TIME(0,40,0), IF(E4="CIP 2",TIME(2,30,0), IF(E4="CIP 3",TIME(3,20,0), IF(AND(ISNUMBER(F4),ISNUMBER(D4),D4>0),F4/D4/24,"Ошибка"))))))))) -> 0.10416667 | E4: CIP 2 | H4: =IFERROR(Линия3[[#This Row],[Количество]]/Линия3[[#This Row],[Шт. в поддоне]], "")
A5: =B4 -> 45996.646 | B5: =Линия3[[#This Row],[Дата начала]]+Линия3[[#This Row],[Длительность]] -> 45997.029 | C5: =IF(E5="Вытеснение",TIME(0,30,0), IF(E5="Передача смены",TIME(0,20,0), IF(E5="Запуск",TIME(0,30,0), IF(E5="Смена ассортимента",TIME(0,15,0), IF(E5="Переналадка формата",TIME(5,0,0), IF(E5="CIP 1",TIME(0,40,0), IF(E5="CIP 2",TIME(2,30,0), IF(E5="CIP 3",TIME(3,20,0), IF(AND(ISNUMBER(F5),ISNUMBER(D5),D5>0),F5/D5/24,"Ошибка"))))))))) -> 0.38288288 | D5: 3700 | E5: Нектар Тыква 0,75 л ТМ «Soko GRANDE» | F5: 34000 | G5: 756 | H5: =IFERROR(Линия3[[#This Row],[Количество]]/Линия3[[#This Row],[Шт. в поддоне]], "") -> 44.973545
A6: =B5 -> 45997.029 | B6: =Линия3[[#This Row],[Дата начала]]+Линия3[[#This Row],[Длительность]] -> 45997.039 | C6: =IF(E6="Вытеснение",TIME(0,30,0), IF(E6="Передача смены",TIME(0,20,0), IF(E6="Запуск",TIME(0,30,0), IF(E6="Смена ассортимента",TIME(0,15,0), IF(E6="Переналадка формата",TIME(5,0,0), IF(E6="CIP 1",TIME(0,40,0), IF(E6="CIP 2",TIME(2,30,0), IF(E6="CIP 3",TIME(3,20,0), IF(AND(ISNUMBER(F6),ISNUMBER(D6),D6>0),F6/D6/24,"Ошибка"))))))))) -> 0.010416667 | E6: Смена ассортимента | H6: =IFERROR(Линия3[[#This Row],[Количество]]/Линия3[[#This Row],[Шт. в поддоне]], "")
A7: =B6 -> 45997.039 | B7: =Линия3[[#This Row],[Дата начала]]+Линия3[[#This Row],[Длительность]] -> 45997.411 | C7: =IF(E7="Вытеснение",TIME(0,30,0), IF(E7="Передача смены",TIME(0,20,0), IF(E7="Запуск",TIME(0,30,0), IF(E7="Смена ассортимента",TIME(0,15,0), IF(E7="Переналадка формата",TIME(5,0,0), IF(E7="CIP 1",TIME(0,40,0), IF(E7="CIP 2",TIME(2,30,0), IF(E7="CIP 3",TIME(3,20,0), IF(AND(ISNUMBER(F7),ISNUMBER(D7),D7>0),F7/D7/24,"Ошибка"))))))))) -> 0.37162162 | D7: 3700 | E7: Нектар Тыква 0,75 л ТМ «Мамина Дача» | F7: 33000 | G7: 756 | H7: =IFERROR(Линия3[[#This Row],[Количество]]/Линия3[[#This Row],[Шт. в поддоне]], "") -> 43.650794
A8: =B7 -> 45997.411 | B8: =Линия3[[#This Row],[Дата начала]]+Линия3[[#This Row],[Длительность]] -> 45997.515 | C8: =IF(E8="Вытеснение",TIME(0,30,0), IF(E8="Передача смены",TIME(0,20,0), IF(E8="Запуск",TIME(0,30,0), IF(E8="Смена ассортимента",TIME(0,15,0), IF(E8="Переналадка формата",TIME(5,0,0), IF(E8="CIP 1",TIME(0,40,0), IF(E8="CIP 2",TIME(2,30,0), IF(E8="CIP 3",TIME(3,20,0), IF(AND(ISNUMBER(F8),ISNUMBER(D8),D8>0),F8/D8/24,"Ошибка"))))))))) -> 0.10416667 | E8: CIP 2 | H8: =IFERROR(Линия3[[#This Row],[Количество]]/Линия3[[#This Row],[Шт. в поддоне]], "")
A9: =B8 -> 45997.515 | B9: =Линия3[[#This Row],[Дата начала]]+Линия3[[#This Row],[Длительность]] -> 45997.808 | C9: =IF(E9="Вытеснение",TIME(0,30,0), IF(E9="Передача смены",TIME(0,20,0), IF(E9="Запуск",TIME(0,30,0), IF(E9="Смена ассортимента",TIME(0,15,0), IF(E9="Переналадка формата",TIME(5,0,0), IF(E9="CIP 1",TIME(0,40,0), IF(E9="CIP 2",TIME(2,30,0), IF(E9="CIP 3",TIME(3,20,0), IF(AND(ISNUMBER(F9),ISNUMBER(D9),D9>0),F9/D9/24,"Ошибка"))))))))) -> 0.29279279 | D9: 3700 | E9: Нектар Облепиха 0,75 л ТМ «Мамина Дача» | F9: 26000 | G9: 756 | H9: =IFERROR(Линия3[[#This Row],[Количество]]/Линия3[[#This Row],[Шт. в поддоне]], "") -> 34.391534
A10: =B9 -> 45997.808 | B10: =Линия3[[#This Row],[Дата начала]]+Линия3[[#This Row],[Длительность]] -> 45997.912 | C10: =IF(E10="Вытеснение",TIME(0,30,0), IF(E10="Передача смены",TIME(0,20,0), IF(E10="Запуск",TIME(0,30,0), IF(E10="Смена ассортимента",TIME(0,15,0), IF(E10="Переналадка формата",TIME(5,0,0), IF(E10="CIP 1",TIME(0,40,0), IF(E10="CIP 2",TIME(2,30,0), IF(E10="CIP 3",TIME(3,20,0), IF(AND(ISNUMBER(F10),ISNUMBER(D10),D10>0),F10/D10/24,"Ошибка"))))))))) -> 0.10416667 | E10: CIP 2 | H10: =IFERROR(Линия3[[#This Row],[Количество]]/Линия3[[#This Row],[Шт. в поддоне]], "")
A11: 45998.167 | B11: =Линия3[[#This Row],[Дата начала]]+Линия3[[#This Row],[Длительность]] -> 45998.529 | C11: =IF(E11="Вытеснение",TIME(0,30,0), IF(E11="Передача смены",TIME(0,20,0), IF(E11="Запуск",TIME(0,30,0), IF(E11="Смена ассортимента",TIME(0,15,0), IF(E11="Переналадка формата",TIME(5,0,0), IF(E11="CIP 1",TIME(0,40,0), IF(E11="CIP 2",TIME(2,30,0), IF(E11="CIP 3",TIME(3,20,0), IF(AND(ISNUMBER(F11),ISNUMBER(D11),D11>0),F11/D11/24,"Ошибка"))))))))) -> 0.36231884 | D11: 4600 | E11: Нектар Манго 0,75 л ТМ «Мамина Дача» | F11: 40000 | G11: 756 | H11: =IFERROR(Линия3[[#This Row],[Количество]]/Линия3[[#This Row],[Шт. в поддоне]], "") -> 52.910053
A12: =B11 -> 45998.529 | B12: =Линия3[[#This Row],[Дата начала]]+Линия3[[#This Row],[Длительность]] -> 45998.633 | C12: =IF(E12="Вытеснение",TIME(0,30,0), IF(E12="Передача смены",TIME(0,20,0), IF(E12="Запуск",TIME(0,30,0), IF(E12="Смена ассортимента",TIME(0,15,0), IF(E12="Переналадка формата",TIME(5,0,0), IF(E12="CIP 1",TIME(0,40,0), IF(E12="CIP 2",TIME(2,30,0), IF(E12="CIP 3",TIME(3,20,0), IF(AND(ISNUMBER(F12),ISNUMBER(D12),D12>0),F12/D12/24,"Ошибка"))))))))) -> 0.10416667 | E12: CIP 2 | H12: =IFERROR(Линия3[[#This Row],[Количество]]/Линия3[[#This Row],[Шт. в поддоне]], "")
A13: 45999.021 | B13: =Линия3[[#This Row],[Дата начала]]+Линия3[[#This Row],[Длительность]] -> 45999.764 | C13: =IF(E13="Вытеснение",TIME(0,30,0), IF(E13="Передача смены",TIME(0,20,0), IF(E13="Запуск",TIME(0,30,0), IF(E13="Смена ассортимента",TIME(0,15,0), IF(E13="Переналадка формата",TIME(5,0,0), IF(E13="CIP 1",TIME(0,40,0), IF(E13="CIP 2",TIME(2,30,0), IF(E13="CIP 3",TIME(3,20,0), IF(AND(ISNUMBER(F13),ISNUMBER(D13),D13>0),F13/D13/24,"Ошибка"))))))))) -> 0.74324324 | D13: 3700 | E13: Нектар Тыква 0,75 л ТМ «Soko GRANDE» | F13: 66000 | G13: 756 | H13: =IFERROR(Линия3[[#This Row],[Количество]]/Линия3[[#This Row],[Шт. в поддоне]], "") -> 87.301587
A14: =B13 -> 45999.764 | B14: =Линия3[[#This Row],[Дата начала]]+Линия3[[#This Row],[Длительность]] -> 45999.868 | C14: =IF(E14="Вытеснение",TIME(0,30,0), IF(E14="Передача смены",TIME(0,20,0), IF(E14="Запуск",TIME(0,30,0), IF(E14="Смена ассортимента",TIME(0,15,0), IF(E14="Переналадка формата",TIME(5,0,0), IF(E14="CIP 1",TIME(0,40,0), IF(E14="CIP 2",TIME(2,30,0), IF(E14="CIP 3",TIME(3,20,0), IF(AND(ISNUMBER(F14),ISNUMBER(D14),D14>0),F14/D14/24,"Ошибка"))))))))) -> 0.10416667 | E14: CIP 2 | H14: =IFERROR(Линия3[[#This Row],[Количество]]/Линия3[[#This Row],[Шт. в поддоне]], "")
A15: =B14 -> 45999.868 | B15: =Линия3[[#This Row],[Дата начала]]+Линия3[[#This Row],[Длительность]] -> 46000.319 | C15: =IF(E15="Вытеснение",TIME(0,30,0), IF(E15="Передача смены",TIME(0,20,0), IF(E15="Запуск",TIME(0,30,0), IF(E15="Смена ассортимента",TIME(0,15,0), IF(E15="Переналадка формата",TIME(5,0,0), IF(E15="CIP 1",TIME(0,40,0), IF(E15="CIP 2",TIME(2,30,0), IF(E15="CIP 3",TIME(3,20,0), IF(AND(ISNUMBER(F15),ISNUMBER(D15),D15>0),F15/D15/24,"Ошибка"))))))))) -> 0.45045045 | D15: 3700 | E15: Сок Томат 0,75 л ТМ «Мамина Дача» | F15: 40000 | G15: 756 | H15: =IFERROR(Линия3[[#This Row],[Количество]]/Линия3[[#This Row],[Шт. в поддоне]], "") -> 52.910053
A16: =B15 -> 46000.319 | B16: =Линия3[[#This Row],[Дата начала]]+Линия3[[#This Row],[Длительность]] -> 46000.527 | C16: 0.20833333 | E16: CIP 3 + Переналадка на прайм | H16: =IFERROR(Линия3[[#This Row],[Количество]]/Линия3[[#This Row],[Шт. в поддоне]], "")
A17: 46000.604 | B17: =Линия3[[#This Row],[Дата начала]]+Линия3[[#This Row],[Длительность]] -> 46001.057 | C17: =IF(E17="Вытеснение",TIME(0,30,0), IF(E17="Передача смены",TIME(0,20,0), IF(E17="Запуск",TIME(0,30,0), IF(E17="Смена ассортимента",TIME(0,15,0), IF(E17="Переналадка формата",TIME(5,0,0), IF(E17="CIP 1",TIME(0,40,0), IF(E17="CIP 2",TIME(2,30,0), IF(E17="CIP 3",TIME(3,20,0), IF(AND(ISNUMBER(F17),ISNUMBER(D17),D17>0),F17/D17/24,"Ошибка"))))))))) -> 0.45289855 | D17: 4600 | E17: Нектар Морковь 1,0 л ТМ «Баринофф» | F17: 50000 | G17: 504 | H17: =IFERROR(Линия3[[#This Row],[Количество]]/Линия3[[#This Row],[Шт. в поддоне]], "") -> 99.206349
A18: =B17 -> 46001.057 | B18: =Линия3[[#This Row],[Дата начала]]+Линия3[[#This Row],[Длительность]] -> 46001.161 | C18: =IF(E18="Вытеснение",TIME(0,30,0), IF(E18="Передача смены",TIME(0,20,0), IF(E18="Запуск",TIME(0,30,0), IF(E18="Смена ассортимента",TIME(0,15,0), IF(E18="Переналадка формата",TIME(5,0,0), IF(E18="CIP 1",TIME(0,40,0), IF(E18="CIP 2",TIME(2,30,0), IF(E18="CIP 3",TIME(3,20,0), IF(AND(ISNUMBER(F18),ISNUMBER(D18),D18>0),F18/D18/24,"Ошибка"))))))))) -> 0.10416667 | E18: CIP 2 | H18: =IFERROR(Линия3[[#This Row],[Количество]]/Линия3[[#This Row],[Шт. в поддоне]], "")
A19: 46001.479 | B19: =Линия3[[#This Row],[Дата начала]]+Линия3[[#This Row],[Длительность]] -> 46001.932 | C19: =IF(E19="Вытеснение",TIME(0,30,0), IF(E19="Передача смены",TIME(0,20,0), IF(E19="Запуск",TIME(0,30,0), IF(E19="Смена ассортимента",TIME(0,15,0), IF(E19="Переналадка формата",TIME(5,0,0), IF(E19="CIP 1",TIME(0,40,0), IF(E19="CIP 2",TIME(2,30,0), IF(E19="CIP 3",TIME(3,20,0), IF(AND(ISNUMBER(F19),ISNUMBER(D19),D19>0),F19/D19/24,"Ошибка"))))))))) -> 0.45289855 | D19: 4600 | E19: Сок Томат 1,0 л ТМ «Баринофф» | F19: 50000 | G19: 504 | H19: =IFERROR(Линия3[[#This Row],[Количество]]/Линия3[[#This Row],[Шт. в поддоне]], "") -> 99.206349
A20: =B19 -> 46001.932 | B20: =Линия3[[#This Row],[Дата начала]]+Линия3[[#This Row],[Длительность]] -> 46002.071 | C20: =IF(E20="Вытеснение",TIME(0,30,0), IF(E20="Передача смены",TIME(0,20,0), IF(E20="Запуск",TIME(0,30,0), IF(E20="Смена ассортимента",TIME(0,15,0), IF(E20="Переналадка формата",TIME(5,0,0), IF(E20="CIP 1",TIME(0,40,0), IF(E20="CIP 2",TIME(2,30,0), IF(E20="CIP 3",TIME(3,20,0), IF(AND(ISNUMBER(F20),ISNUMBER(D20),D20>0),F20/D20/24,"Ошибка"))))))))) -> 0.13888889 | E20: CIP 3 | H20: =IFERROR(Линия3[[#This Row],[Количество]]/Линия3[[#This Row],[Шт. в поддоне]], "")
A21: =B20 -> 46002.071 | B21: =Линия3[[#This Row],[Дата начала]]+Линия3[[#This Row],[Длительность]] -> 46002.524 | C21: =IF(E21="Вытеснение",TIME(0,30,0), IF(E21="Передача смены",TIME(0,20,0), IF(E21="Запуск",TIME(0,30,0), IF(E21="Смена ассортимента",TIME(0,15,0), IF(E21="Переналадка формата",TIME(5,0,0), IF(E21="CIP 1",TIME(0,40,0), IF(E21="CIP 2",TIME(2,30,0), IF(E21="CIP 3",TIME(3,20,0), IF(AND(ISNUMBER(F21),ISNUMBER(D21),D21>0),F21/D21/24,"Ошибка"))))))))) -> 0.45289855 | D21: 4600 | E21: Нектар Манго 1,0 л ТМ «Баринофф» | F21: 50000 | G21: 504 | H21: =IFERROR(Линия3[[#This Row],[Количество]]/Линия3[[#This Row],[Шт. в поддоне]], "") -> 99.206349
A22: =B21 -> 46002.524 | B22: =Линия3[[#This Row],[Дата начала]]+Линия3[[#This Row],[Длительность]] -> 46002.545 | C22: =IF(E22="Вытеснение",TIME(0,30,0), IF(E22="Передача смены",TIME(0,20,0), IF(E22="Запуск",TIME(0,30,0), IF(E22="Смена ассортимента",TIME(0,15,0), IF(E22="Переналадка формата",TIME(5,0,0), IF(E22="CIP 1",TIME(0,40,0), IF(E22="CIP 2",TIME(2,30,0), IF(E22="CIP 3",TIME(3,20,0), IF(AND(ISNUMBER(F22),ISNUMBER(D22),D22>0),F22/D22/24,"Ошибка"))))))))) -> 0.020833333 | E22: вытеснение | H22: =IFERROR(Линия3[[#This Row],[Количество]]/Линия3[[#This Row],[Шт. в поддоне]], "")
A23: 46003.292 | B23: =Линия3[[#This Row],[Дата начала]]+Линия3[[#This Row],[Длительность]] -> 46003.654 | C23: =IF(E23="Вытеснение",TIME(0,30,0), IF(E23="Передача смены",TIME(0,20,0), IF(E23="Запуск",TIME(0,30,0), IF(E23="Смена ассортимента",TIME(0,15,0), IF(E23="Переналадка формата",TIME(5,0,0), IF(E23="CIP 1",TIME(0,40,0), IF(E23="CIP 2",TIME(2,30,0), IF(E23="CIP 3",TIME(3,20,0), IF(AND(ISNUMBER(F23),ISNUMBER(D23),D23>0),F23/D23/24,"Ошибка"))))))))) -> 0.36231884 | D23: 4600 | E23: Нектар Персик 1,0 л ТМ «Баринофф» | F23: 40000 | G23: 504 | H23: =IFERROR(Линия3[[#This Row],[Количество]]/Линия3[[#This Row],[Шт. в поддоне]], "") -> 79.365079
A24: =B23 -> 46003.654 | B24: =Линия3[[#This Row],[Дата начала]]+Линия3[[#This Row],[Длительность]] -> 46003.758 | C24: =IF(E24="Вытеснение",TIME(0,30,0), IF(E24="Передача смены",TIME(0,20,0), IF(E24="Запуск",TIME(0,30,0), IF(E24="Смена ассортимента",TIME(0,15,0), IF(E24="Переналадка формата",TIME(5,0,0), IF(E24="CIP 1",TIME(0,40,0), IF(E24="CIP 2",TIME(2,30,0), IF(E24="CIP 3",TIME(3,20,0), IF(AND(ISNUMBER(F24),ISNUMBER(D24),D24>0),F24/D24/24,"Ошибка"))))))))) -> 0.10416667 | E24: CIP 2 | H24: =IFERROR(Линия3[[#This Row],[Количество]]/Линия3[[#This Row],[Шт. в поддоне]], "")
A25: =B24 -> 46003.758 | B25: =Линия3[[#This Row],[Дата начала]]+Линия3[[#This Row],[Длительность]] -> 46004.03 | C25: =IF(E25="Вытеснение",TIME(0,30,0), IF(E25="Передача смены",TIME(0,20,0), IF(E25="Запуск",TIME(0,30,0), IF(E25="Смена ассортимента",TIME(0,15,0), IF(E25="Переналадка формата",TIME(5,0,0), IF(E25="CIP 1",TIME(0,40,0), IF(E25="CIP 2",TIME(2,30,0), IF(E25="CIP 3",TIME(3,20,0), IF(AND(ISNUMBER(F25),ISNUMBER(D25),D25>0),F25/D25/24,"Ошибка"))))))))) -> 0.27173913 | D25: 4600 | E25: Сок Апельсин 1,0 л ТМ «Баринофф» | F25: 30000 | G25: 504 | H25: =IFERROR(Линия3[[#This Row],[Количество]]/Линия3[[#This Row],[Шт. в поддоне]], "") -> 59.52381
A26: =B25 -> 46004.03 | B26: =Линия3[[#This Row],[Дата начала]]+Линия3[[#This Row],[Длительность]] -> 46004.051 | C26: =IF(E26="Вытеснение",TIME(0,30,0), IF(E26="Передача смены",TIME(0,20,0), IF(E26="Запуск",TIME(0,30,0), IF(E26="Смена ассортимента",TIME(0,15,0), IF(E26="Переналадка формата",TIME(5,0,0), IF(E26="CIP 1",TIME(0,40,0), IF(E26="CIP 2",TIME(2,30,0), IF(E26="CIP 3",TIME(3,20,0), IF(AND(ISNUMBER(F26),ISNUMBER(D26),D26>0),F26/D26/24,"Ошибка"))))))))) -> 0.020833333 | E26: вытеснение | H26: =IFERROR(Линия3[[#This Row],[Количество]]/Линия3[[#This Row],[Шт. в поддоне]], "")
A27: =B26 -> 46004.051 | B27: =Линия3[[#This Row],[Дата начала]]+Линия3[[#This Row],[Длительность]] -> 46004.322 | C27: =IF(E27="Вытеснение",TIME(0,30,0), IF(E27="Передача смены",TIME(0,20,0), IF(E27="Запуск",TIME(0,30,0), IF(E27="Смена ассортимента",TIME(0,15,0), IF(E27="Переналадка формата",TIME(5,0,0), IF(E27="CIP 1",TIME(0,40,0), IF(E27="CIP 2",TIME(2,30,0), IF(E27="CIP 3",TIME(3,20,0), IF(AND(ISNUMBER(F27),ISNUMBER(D27),D27>0),F27/D27/24,"Ошибка"))))))))) -> 0.27173913 | D27: 4600 | E27: Нектар Мультифрукт 1,0 л ТМ «Баринофф» | F27: 30000 | G27: 504 | H27: =IFERROR(Линия3[[#This Row],[Количество]]/Линия3[[#This Row],[Шт. в поддоне]], "") -> 59.52381
A28: =B27 -> 46004.322 | B28: =Линия3[[#This Row],[Дата начала]]+Линия3[[#This Row],[Длительность]] -> 46004.427 | C28: =IF(E28="Вытеснение",TIME(0,30,0), IF(E28="Передача смены",TIME(0,20,0), IF(E28="Запуск",TIME(0,30,0), IF(E28="Смена ассортимента",TIME(0,15,0), IF(E28="Переналадка формата",TIME(5,0,0), IF(E28="CIP 1",TIME(0,40,0), IF(E28="CIP 2",TIME(2,30,0), IF(E28="CIP 3",TIME(3,20,0), IF(AND(ISNUMBER(F28),ISNUMBER(D28),D28>0),F28/D28/24,"Ошибка"))))))))) -> 0.10416667 | E28: CIP 2 | H28: =IFERROR(Линия3[[#This Row],[Количество]]/Линия3[[#This Row],[Шт. в поддоне]], "")
A29: =B28 -> 46004.427 | B29: =Линия3[[#This Row],[Дата начала]]+Линия3[[#This Row],[Длительность]] -> 46004.764 | C29: =IF(E29="Вытеснение",TIME(0,30,0), IF(E29="Передача смены",TIME(0,20,0), IF(E29="Запуск",TIME(0,30,0), IF(E29="Смена ассортимента",TIME(0,15,0), IF(E29="Переналадка формата",TIME(5,0,0), IF(E29="CIP 1",TIME(0,40,0), IF(E29="CIP 2",TIME(2,30,0), IF(E29="CIP 3",TIME(3,20,0), IF(AND(ISNUMBER(F29),ISNUMBER(D29),D29>0),F29/D29/24,"Ошибка"))))))))) -> 0.33783784 | D29: 3700 | E29: Сок Груша 1,0 л ТМ «Баринофф» | F29: 30000 | G29: 504 | H29: =IFERROR(Линия3[[#This Row],[Количество]]/Линия3[[#This Row],[Шт. в поддоне]], "") -> 59.52381
A30: =B29 -> 46004.764 | B30: =Линия3[[#This Row],[Дата начала]]+Линия3[[#This Row],[Длительность]] -> 46004.903 | C30: =IF(E30="Вытеснение",TIME(0,30,0), IF(E30="Передача смены",TIME(0,20,0), IF(E30="Запуск",TIME(0,30,0), IF(E30="Смена ассортимента",TIME(0,15,0), IF(E30="Переналадка формата",TIME(5,0,0), IF(E30="CIP 1",TIME(0,40,0), IF(E30="CIP 2",TIME(2,30,0), IF(E30="CIP 3",TIME(3,20,0), IF(AND(ISNUMBER(F30),ISNUMBER(D30),D30>0),F30/D30/24,"Ошибка"))))))))) -> 0.13888889 | E30: CIP 3 | H30: =IFERROR(Линия3[[#This Row],[Количество]]/Линия3[[#This Row],[Шт. в поддоне]], "")
A31: =B30 -> 46004.903 | B31: =Линия3[[#This Row],[Дата начала]]+Линия3[[#This Row],[Длительность]] -> 46005.466 | C31: =IF(E31="Вытеснение",TIME(0,30,0), IF(E31="Передача смены",TIME(0,20,0), IF(E31="Запуск",TIME(0,30,0), IF(E31="Смена ассортимента",TIME(0,15,0), IF(E31="Переналадка формата",TIME(5,0,0), IF(E31="CIP 1",TIME(0,40,0), IF(E31="CIP 2",TIME(2,30,0), IF(E31="CIP 3",TIME(3,20,0), IF(AND(ISNUMBER(F31),ISNUMBER(D31),D31>0),F31/D31/24,"Ошибка"))))))))) -> 0.56306306 | D31: 3700 | E31: Нектар Тыква 1,0 л ТМ «Баринофф» | F31: 50000 | G31: 504 | H31: =IFERROR(Линия3[[#This Row],[Количество]]/Линия3[[#This Row],[Шт. в поддоне]], "") -> 99.206349
A32: =B31 -> 46005.466 | B32: =Линия3[[#This Row],[Дата начала]]+Линия3[[#This Row],[Длительность]] -> 46005.571 | C32: =IF(E32="Вытеснение",TIME(0,30,0), IF(E32="Передача смены",TIME(0,20,0), IF(E32="Запуск",TIME(0,30,0), IF(E32="Смена ассортимента",TIME(0,15,0), IF(E32="Переналадка формата",TIME(5,0,0), IF(E32="CIP 1",TIME(0,40,0), IF(E32="CIP 2",TIME(2,30,0), IF(E32="CIP 3",TIME(3,20,0), IF(AND(ISNUMBER(F32),ISNUMBER(D32),D32>0),F32/D32/24,"Ошибка"))))))))) -> 0.10416667 | E32: CIP 2 | H32: =IFERROR(Линия3[[#This Row],[Количество]]/Линия3[[#This Row],[Шт. в поддоне]], "")
A33: =B32 -> 46005.571 | B33: =Линия3[[#This Row],[Дата начала]]+Линия3[[#This Row],[Длительность]] -> 46006.246 | C33: =IF(E33="Вытеснение",TIME(0,30,0), IF(E33="Передача смены",TIME(0,20,0), IF(E33="Запуск",TIME(0,30,0), IF(E33="Смена ассортимента",TIME(0,15,0), IF(E33="Переналадка формата",TIME(5,0,0), IF(E33="CIP 1",TIME(0,40,0), IF(E33="CIP 2",TIME(2,30,0), IF(E33="CIP 3",TIME(3,20,0), IF(AND(ISNUMBER(F33),ISNUMBER(D33),D33>0),F33/D33/24,"Ошибка"))))))))) -> 0.67567568 | D33: 3700 | E33: Сок Гранат 1,0 л ТМ «Баринофф» | F33: 60000 | G33: 504 | H33: =IFERROR(Линия3[[#This Row],[Количество]]/Линия3[[#This Row],[Шт. в поддоне]], "") -> 119.04762
A34: =B33 -> 46006.246 | B34: =Линия3[[#This Row],[Дата начала]]+Линия3[[#This Row],[Длительность]] -> 46006.385 | C34: =IF(E34="Вытеснение",TIME(0,30,0), IF(E34="Передача смены",TIME(0,20,0), IF(E34="Запуск",TIME(0,30,0), IF(E34="Смена ассортимента",TIME(0,15,0), IF(E34="Переналадка формата",TIME(5,0,0), IF(E34="CIP 1",TIME(0,40,0), IF(E34="CIP 2",TIME(2,30,0), IF(E34="CIP 3",TIME(3,20,0), IF(AND(ISNUMBER(F34),ISNUMBER(D34),D34>0),F34/D34/24,"Ошибка"))))))))) -> 0.13888889 | E34: CIP 3 | H34: =IFERROR(Линия3[[#This Row],[Количество]]/Линия3[[#This Row],[Шт. в поддоне]], "")
A35: 46007.469 | B35: =Линия3[[#This Row],[Дата начала]]+Линия3[[#This Row],[Длительность]] -> 46007.741 | C35: =IF(E35="Вытеснение",TIME(0,30,0), IF(E35="Передача смены",TIME(0,20,0), IF(E35="Запуск",TIME(0,30,0), IF(E35="Смена ассортимента",TIME(0,15,0), IF(E35="Переналадка формата",TIME(5,0,0), IF(E35="CIP 1",TIME(0,40,0), IF(E35="CIP 2",TIME(2,30,0), IF(E35="CIP 3",TIME(3,20,0), IF(AND(ISNUMBER(F35),ISNUMBER(D35),D35>0),F35/D35/24,"Ошибка"))))))))) -> 0.27173913 | D35: 4600 | E35: Сок Яблоко 1,0 л ТМ «Баринофф» | F35: 30000 | G35: 504 | H35: =IFERROR(Линия3[[#This Row],[Количество]]/Линия3[[#This Row],[Шт. в поддоне]], "") -> 59.52381
A36: =B35 -> 46007.741 | B36: =Линия3[[#This Row],[Дата начала]]+Линия3[[#This Row],[Длительность]] -> 46007.769 | C36: =IF(E36="Вытеснение",TIME(0,30,0), IF(E36="Передача смены",TIME(0,20,0), IF(E36="Запуск",TIME(0,30,0), IF(E36="Смена ассортимента",TIME(0,15,0), IF(E36="Переналадка формата",TIME(5,0,0), IF(E36="CIP 1",TIME(0,40,0), IF(E36="CIP 2",TIME(2,30,0), IF(E36="CIP 3",TIME(3,20,0), IF(AND(ISNUMBER(F36),ISNUMBER(D36),D36>0),F36/D36/24,"Ошибка"))))))))) -> 0.027777778 | E36: CIP 1 | H36: =IFERROR(Линия3[[#This Row],[Количество]]/Линия3[[#This Row],[Шт. в поддоне]], "")
A37: 46008 | B37: =Линия3[[#This Row],[Дата начала]]+Линия3[[#This Row],[Длительность]] -> 46008.272 | C37: =IF(E37="Вытеснение",TIME(0,30,0), IF(E37="Передача смены",TIME(0,20,0), IF(E37="Запуск",TIME(0,30,0), IF(E37="Смена ассортимента",TIME(0,15,0), IF(E37="Переналадка формата",TIME(5,0,0), IF(E37="CIP 1",TIME(0,40,0), IF(E37="CIP 2",TIME(2,30,0), IF(E37="CIP 3",TIME(3,20,0), IF(AND(ISNUMBER(F37),ISNUMBER(D37),D37>0),F37/D37/24,"Ошибка"))))))))) -> 0.27173913 | D37: 4600 | E37: Нектар Вишня 1,0 л ТМ «Баринофф» | F37: 30000 | G37: 504 | H37: =IFERROR(Линия3[[#This Row],[Количество]]/Линия3[[#This Row],[Шт. в поддоне]], "") -> 59.52381
A38: =B37 -> 46008.272 | B38: =Линия3[[#This Row],[Дата начала]]+Линия3[[#This Row],[Длительность]] -> 46008.376 | C38: =IF(E38="Вытеснение",TIME(0,30,0), IF(E38="Передача смены",TIME(0,20,0), IF(E38="Запуск",TIME(0,30,0), IF(E38="Смена ассортимента",TIME(0,15,0), IF(E38="Переналадка формата",TIME(5,0,0), IF(E38="CIP 1",TIME(0,40,0), IF(E38="CIP 2",TIME(2,30,0), IF(E38="CIP 3",TIME(3,20,0), IF(AND(ISNUMBER(F38),ISNUMBER(D38),D38>0),F38/D38/24,"Ошибка"))))))))) -> 0.10416667 | E38: CIP 2 | H38: =IFERROR(Линия3[[#This Row],[Количество]]/Линия3[[#This Row],[Шт. в поддоне]], "")
A39: 46008.875 | B39: =Линия3[[#This Row],[Дата начала]]+Линия3[[#This Row],[Длительность]] -> 46009.325 | C39: =IF(E39="Вытеснение",TIME(0,30,0), IF(E39="Передача смены",TIME(0,20,0), IF(E39="Запуск",TIME(0,30,0), IF(E39="Смена ассортимента",TIME(0,15,0), IF(E39="Переналадка формата",TIME(5,0,0), IF(E39="CIP 1",TIME(0,40,0), IF(E39="CIP 2",TIME(2,30,0), IF(E39="CIP 3",TIME(3,20,0), IF(AND(ISNUMBER(F39),ISNUMBER(D39),D39>0),F39/D39/24,"Ошибка"))))))))) -> 0.45045045 | D39: 3700 | E39: Нектар Морковь 1,0 л ТМ «Баринофф» | F39: 40000 | G39: 504 | H39: =IFERROR(Линия3[[#This Row],[Количество]]/Линия3[[#This Row],[Шт. в поддоне]], "") -> 79.365079
A40: =B39 -> 46009.325 | B40: =Линия3[[#This Row],[Дата начала]]+Линия3[[#This Row],[Длительность]] -> 46009.45 | C40: 0.125 | E40: CIP 2 + переналадка на Бриолу | H40: =IFERROR(Линия3[[#This Row],[Количество]]/Линия3[[#This Row],[Шт. в поддоне]], "")
...

Sheet Линия 4
A1: Линия розлива №4
A2: Дата начала | B2: Дата конца | C2: Длительность | D2: Скорость | E2: Наименование | F2: Количество | G2: Шт. в поддоне | H2: Кол-во поддоном
C3: =IF(E3="Вытеснение",TIME(0,30,0), IF(E3="Передача смены",TIME(0,20,0), IF(E3="Запуск",TIME(0,30,0), IF(E3="Смена ассортимента",TIME(0,15,0), IF(E3="Переналадка формата",TIME(5,0,0), IF(E3="CIP 1",TIME(2,30,0), IF(E3="CIP 2",TIME(2,30,0), IF(E3="CIP 3",TIME(3,20,0), IF(AND(ISNUMBER(F3),ISNUMBER(D3),D3>0),F3/D3/24,"Ошибка"))))))))) -> 0.21969697 | D3: 5500 | E3: Нектар Тыква-Манго 0,33 ТМ «Вау Мяу» | F3: 29000 | G3: 1470 | H3: =IFERROR(Линия4[[#This Row],[Количество]]/Линия4[[#This Row],[Шт. в поддоне]], "") -> 19.727891
C4: =IF(E4="Вытеснение",TIME(0,30,0), IF(E4="Передача смены",TIME(0,20,0), IF(E4="Запуск",TIME(0,30,0), IF(E4="Смена ассортимента",TIME(0,15,0), IF(E4="Переналадка формата",TIME(5,0,0), IF(E4="CIP 1",TIME(2,30,0), IF(E4="CIP 2",TIME(2,30,0), IF(E4="CIP 3",TIME(3,20,0), IF(AND(ISNUMBER(F4),ISNUMBER(D4),D4>0),F4/D4/24,"Ошибка"))))))))) -> 0.10416667 | E4: CIP 2 | H4: =IFERROR(Линия4[[#This Row],[Количество]]/Линия4[[#This Row],[Шт. в поддоне]], "")
C5: =IF(E5="Вытеснение",TIME(0,30,0), IF(E5="Передача смены",TIME(0,20,0), IF(E5="Запуск",TIME(0,30,0), IF(E5="Смена ассортимента",TIME(0,15,0), IF(E5="Переналадка формата",TIME(5,0,0), IF(E5="CIP 1",TIME(2,30,0), IF(E5="CIP 2",TIME(2,30,0), IF(E5="CIP 3",TIME(3,20,0), IF(AND(ISNUMBER(F5),ISNUMBER(D5),D5>0),F5/D5/24,"Ошибка"))))))))) -> 0.020833333 | E5: Запуск | H5: =IFERROR(Линия4[[#This Row],[Количество]]/Линия4[[#This Row],[Шт. в поддоне]], "")
C6: =IF(E6="Вытеснение",TIME(0,30,0), IF(E6="Передача смены",TIME(0,20,0), IF(E6="Запуск",TIME(0,30,0), IF(E6="Смена ассортимента",TIME(0,15,0), IF(E6="Переналадка формата",TIME(5,0,0), IF(E6="CIP 1",TIME(2,30,0), IF(E6="CIP 2",TIME(2,30,0), IF(E6="CIP 3",TIME(3,20,0), IF(AND(ISNUMBER(F6),ISNUMBER(D6),D6>0),F6/D6/24,"Ошибка"))))))))) -> 0.075757576 | D6: 5500 | E6: Нектар Морковь 0,33 ТМ «Spar Kids» | F6: 10000 | G6: 1470 | H6: =IFERROR(Линия4[[#This Row],[Количество]]/Линия4[[#This Row],[Шт. в поддоне]], "") -> 6.8027211
C7: =IF(E7="Вытеснение",TIME(0,30,0), IF(E7="Передача смены",TIME(0,20,0), IF(E7="Запуск",TIME(0,30,0), IF(E7="Смена ассортимента",TIME(0,15,0), IF(E7="Переналадка формата",TIME(5,0,0), IF(E7="CIP 1",TIME(2,30,0), IF(E7="CIP 2",TIME(2,30,0), IF(E7="CIP 3",TIME(3,20,0), IF(AND(ISNUMBER(F7),ISNUMBER(D7),D7>0),F7/D7/24,"Ошибка"))))))))) -> 0.010416667 | E7: Смена ассортимента | H7: =IFERROR(Линия4[[#This Row],[Количество]]/Линия4[[#This Row],[Шт. в поддоне]], "")
C8: =IF(E8="Вытеснение",TIME(0,30,0), IF(E8="Передача смены",TIME(0,20,0), IF(E8="Запуск",TIME(0,30,0), IF(E8="Смена ассортимента",TIME(0,15,0), IF(E8="Переналадка формата",TIME(5,0,0), IF(E8="CIP 1",TIME(2,30,0), IF(E8="CIP 2",TIME(2,30,0), IF(E8="CIP 3",TIME(3,20,0), IF(AND(ISNUMBER(F8),ISNUMBER(D8),D8>0),F8/D8/24,"Ошибка"))))))))) -> 0.020833333 | E8: Запуск | H8: =IFERROR(Линия4[[#This Row],[Количество]]/Линия4[[#This Row],[Шт. в поддоне]], "")
C9: =IF(E9="Вытеснение",TIME(0,30,0), IF(E9="Передача смены",TIME(0,20,0), IF(E9="Запуск",TIME(0,30,0), IF(E9="Смена ассортимента",TIME(0,15,0), IF(E9="Переналадка формата",TIME(5,0,0), IF(E9="CIP 1",TIME(2,30,0), IF(E9="CIP 2",TIME(2,30,0), IF(E9="CIP 3",TIME(3,20,0), IF(AND(ISNUMBER(F9),ISNUMBER(D9),D9>0),F9/D9/24,"Ошибка"))))))))) -> 0.18939394 | D9: 5500 | E9: Нектар Морковь 0,33 ТМ «Вау Мяу» | F9: 25000 | G9: 1470 | H9: =IFERROR(Линия4[[#This Row],[Количество]]/Линия4[[#This Row],[Шт. в поддоне]], "") -> 17.006803
C10: =IF(E10="Вытеснение",TIME(0,30,0), IF(E10="Передача смены",TIME(0,20,0), IF(E10="Запуск",TIME(0,30,0), IF(E10="Смена ассортимента",TIME(0,15,0), IF(E10="Переналадка формата",TIME(5,0,0), IF(E10="CIP 1",TIME(2,30,0), IF(E10="CIP 2",TIME(2,30,0), IF(E10="CIP 3",TIME(3,20,0), IF(AND(ISNUMBER(F10),ISNUMBER(D10),D10>0),F10/D10/24,"Ошибка"))))))))) -> 0.010416667 | E10: Смена ассортимента | H10: =IFERROR(Линия4[[#This Row],[Количество]]/Линия4[[#This Row],[Шт. в поддоне]], "")
